Tests/report-example/data/attachments/2a8f64130c6df5ad.txt
[2022-04-17 15:47:53] LINE_61: price: Trying to set a new price (100) for the request with id "0"
[2022-04-17 15:47:53] LINE_74: price: A new price was set successfully
[2022-04-17 15:47:53] LINE_95: volume: Trying to set a new volume (5) for the request with id "0"
[2022-04-17 15:47:53] LINE_41: __init__: A new request was created: {'id': 0, 'price': 100, 'volume': 5, 'type': ''}
[2022-04-17 15:47:53] LINE_61: price: Trying to set a new price (100) for the request with id "1"
[2022-04-17 15:47:53] LINE_74: price: A new price was set successfully
[2022-04-17 15:47:53] LINE_95: volume: Trying to set a new volume (5) for the request with id "1"
[2022-04-17 15:47:53] LINE_41: __init__: A new request was created: {'id': 1, 'price': 100, 'volume': 5, 'type': ''}
[2022-04-17 15:47:53] LINE_83: add_request: Trying to add a new request: {'id': 0, 'price': 100, 'volume': 5, 'type': 'Ask'}
[2022-04-17 15:47:53] LINE_156: _get_request: Trying to find the request with id "0"
[2022-04-17 15:47:53] LINE_173: _get_request: The request with id "0" was not found
[2022-04-17 15:47:53] LINE_103: add_request: The request was added successfully
[2022-04-17 15:47:53] LINE_83: add_request: Trying to add a new request: {'id': 1, 'price': 100, 'volume': 5, 'type': 'Bid'}
[2022-04-17 15:47:53] LINE_156: _get_request: Trying to find the request with id "1"
[2022-04-17 15:47:53] LINE_173: _get_request: The request with id "1" was not found
[2022-04-17 15:47:53] LINE_103: add_request: The request was added successfully
[2022-04-17 15:47:53] LINE_252: get_snapshot: A new snapshot was created: {'Asks': [{'price': 100, 'volume': 5}], 'Bids': [{'price': 100, 'volume': 5}]}
[2022-04-17 15:47:53] LINE_252: get_snapshot: A new snapshot was created: {'Asks': [{'price': 100, 'volume': 5}], 'Bids': [{'price': 100, 'volume': 5}]}
